<?xml version = "1.0"?>
<robot xmlns:xacro="http://www.ros.org/wiki/xacro" name = "robot_xacro">


    
    <link name = "base">
        <visual>
            <geometry>
               <box size = "0.94 0.78 1.98"/>
            </geometry>
            <origin xyz = "0 0 0.99"/>
        </visual>
        <collision>
            <geometry>
                <box size = "0.94 0.78 1.98"/>
            </geometry>
            <origin xyz = "0 0 0.99"/>
        </collision>
    </link>

    <xacro:include filename="$(find gazebo_plugins)/test/multi_robot_scenario/xacro/laser/hokuyo.xacro" />
    <!-- the vertical lasers have the Hokuyo LIDAR -->
    <xacro:hokuyo linkname = "laser_vert_bottom"/>
     <!--   <visual>
            <geometry>
                <box size = "0.062 0.062 0.087"/>
            </geometry>
        </visual>
        <collision>
            <geometry>
                <box size = "0.062 0.062 0.087"/>
            </geometry>
        </collision>
    </link> -->
    <!--<xacro:hokuyo linkname = "laser_vert_bottom"/>-->

    <!--<link name = "laser_vert_top_right">
        <visual>
            <geometry>
                <box size = "0.062 0.062 0.087"/>
            </geometry>
        </visual>
        <collision>
            <geometry>
                <box size = "0.062 0.062 0.087"/>
            </geometry>
        </collision>
    </link>-->
    <xacro:hokuyo linkname = "laser_vert_top_right"/>

    <!--<link name = "laser_vert_top_left">
        <visual>
            <geometry>
                <box size = "0.062 0.062 0.087"/>
            </geometry>
        </visual>
        <collision>
            <geometry>
                <box size = "0.062 0.062 0.087"/>
            </geometry>
        </collision>
    </link> -->
    <xacro:hokuyo linkname = "laser_vert_top_left"/>

    <!-- lazer_horiz has the velodyne thing -->

    <xacro:include filename="$(find velodyne_description)/urdf/VLP-16.urdf.xacro"/>

    <!--<link name = "laser_horiz">
        <visual>
            <geometry>
                <cylinder radius = "0.052" length = "0.072"/>
            </geometry>
        </visual>
        <collision>
            <geometry>
                <cylinder radius = "0.052" length = "0.072"/>
            </geometry>
        </collision>
    </link>-->
    <VLP-16 parent = "base" name = "laser_horiz" topic = "laser_horiz/packets" hz = "10" samples = "440" gpu = "false">
        <origin xyz = "0.2325416305773505 -0.0001380069427607134 1.920122926231" rpy = "-0.0012068 0.114646 -0.0015308" />
    </VLP-16>

    <xacro:macro name = "xacro_name" params = "suffix reflect" >
        <link name = "wheel_${suffix}">
            <visual>
                <geometry>
                    <cylinder radius = "0.2" length = "0.05" />
                </geometry>
            </visual>
            <collision>
                <geometry>
                    <cylinder radius = "0.2" length = "0.05" />
                </geometry>
            </collision>
        </link>
        <joint name = "base_wheel_${suffix}_joint" type = "continuous">
            <origin xyz="-0.1 ${reflect * 0.4} 0" rpy = "-1.57079632679 0 0"/>
            <parent link = "base"/>
            <child link = "wheel_${suffix}"/>
            <limit effort = "30" velocity = "2" /> <!-- limit is 30 Newton-meters, 2 m/s -->
            <axis xyz = "0 0 1" />
            <!-- you think it'd be 1 0 0 but this is what got the wheels to actually rotate forward. weird. -->
        </joint>
    </xacro:macro>
    <xacro:xacro_name suffix = "left" reflect = "1"/>
    <xacro:xacro_name suffix = "right" reflect = "-1"/>

    <link name = "wheel_center">
        <visual>
            <geometry>
                <cylinder radius = "0.15" length = "0.05"/>
            </geometry>
        </visual>
        <collision>
            <geometry>
                <cylinder radius = "0.15" length = "0.05"/>
            </geometry>
        </collision>
    </link>

    <joint name = "base_wheel_center_joint" type = "continuous">
        <origin xyz = "0.10 0 -0.05" rpy = "-1.57079632679 0 0"/>
        <parent link = "base"/>
        <child link = "wheel_center"/>
        <limit effort = "30" velocity = "2" /> <!-- limit is 30 Newton-meters, 2 m/s -->
        <axis xyz = "0 0 1" />
        <!-- you think it'd be 1 0 0 but this is what got the wheels to actually rotate forward. weird. -->
    </joint>

    <joint name = "base_laser_vert_bottom_joint" type = "fixed">
        <origin xyz = "0.3158 -0.0021 0.51" rpy = "3.1355 -1.3045 0.0025" />
        <parent link = "base"/>
        <child link = "laser_vert_bottom"/>
    </joint>

    <joint name = "base_laser_vert_top_right_joint" type = "fixed">
        <origin xyz = "0.2978 -0.145 1.8451" rpy = "1.1760 0.6313 -1.9377"/>
        <parent link = "base"/>
        <child link = "laser_vert_top_right"/>
    </joint>

    <joint name = "base_laser_vert_top_left_joint" type = "fixed">
        <origin xyz = "0.2997 0.1531 1.8443" rpy = "1.1780 0.6198 1.9560"/>
        <parent link = "base"/>
        <child link = "laser_vert_top_left"/>
    </joint>

    <!--<joint name = "base_laser_horiz_joint" type = "fixed">
        <origin xyz = "0.2325 0.0001 1.9201" rpy = "-0.0012068 0.114646 -0.0015308"/>
        <parent link = "base"/>
        <child link = "laser_horiz"/>
    </joint> -->
    <!-- don't need this if you're invoking the velodyne thing earlier?? -->
    

</robot>
