<?xml version = "1.0"?>
<robot xmlns:xacro="http://www.ros.org/wiki/xacro" name = "robot_xacro">


    
    <link name = "base">
        <visual>
            <geometry>
               <box size = "0.94 0.78 1.98"/>
            </geometry>
            <origin xyz = "0 0 0.99"/>
        </visual>
        <collision>
            <geometry>
                <box size = "0.94 0.78 1.98"/>
            </geometry>
            <origin xyz = "0 0 0.99"/>
        </collision>
    </link>

    <xacro:include filename="$(find gazebo_plugins)/test/multi_robot_scenario/xacro/laser/hokuyo.xacro" />
    <!-- the vertical lasers have the Hokuyo LIDAR -->
    <xacro:laser name = "laser_vert_bottom" parent = "base" xyz = "0.3157894464801903 -0.002068548615034871 0.5099999434059285" rpy = "3.1354753 -1.3045001 0.0024658" meshes = "package://gazebo_plugins/test/multi_robot_scenario/meshes/laser"/>

    <xacro:laser name = "laser_vert_top_left" parent = "base" xyz = "0.2997 0.1531 1.8443" rpy = "1.1780 0.6198 1.9560" meshes = "package://gazebo_plugins/test/multi_robot_scenario/meshes/laser"/>

    <xacro:laser name = "laser_vert_top_right" parent = "base" xyz = "0.2978 -0.145 1.8451" rpy = "1.1760 0.6313 -1.9377" meshes = "package://gazebo_plugins/test/multi_robot_scenario/meshes/laser" />

    <!-- lazer_horiz has the velodyne thing -->

    <xacro:include filename="$(find velodyne_description)/urdf/VLP-16.urdf.xacro"/>
    <VLP-16 parent = "base" name = "laser_horiz" topic = "laser_horiz/packets" hz = "10" samples = "440" gpu = "false">
        <origin xyz = "0.2325416305773505 -0.0001380069427607134 1.920122926231" rpy = "-0.0012068 0.114646 -0.0015308" />
    </VLP-16>


    <!-- wheels -->

    <xacro:macro name = "xacro_name" params = "suffix reflect" >
        <link name = "wheel_${suffix}">
            <visual>
                <geometry>
                    <cylinder radius = "0.2" length = "0.05" />
                </geometry>
            </visual>
            <collision>
                <geometry>
                    <cylinder radius = "0.2" length = "0.05" />
                </geometry>
            </collision>
        </link>
        <joint name = "base_wheel_${suffix}_joint" type = "continuous">
            <origin xyz="-0.1 ${reflect * 0.4} 0" rpy = "-1.57079632679 0 0"/>
            <parent link = "base"/>
            <child link = "wheel_${suffix}"/>
            <limit effort = "30" velocity = "2" /> <!-- limit is 30 Newton-meters, 2 m/s -->
            <axis xyz = "0 0 1" />
        </joint>
    </xacro:macro>
    <xacro:xacro_name suffix = "left" reflect = "1"/>
    <xacro:xacro_name suffix = "right" reflect = "-1"/>

    <link name = "wheel_center">
        <visual>
            <geometry>
                <cylinder radius = "0.15" length = "0.05"/>
            </geometry>
        </visual>
        <collision>
            <geometry>
                <cylinder radius = "0.15" length = "0.05"/>
            </geometry>
        </collision>
    </link>

    <joint name = "base_wheel_center_joint" type = "continuous">
        <origin xyz = "0.10 0 -0.025" rpy = "-1.57079632679 0 0"/>
        <parent link = "base"/>
        <child link = "wheel_center"/>
        <limit effort = "30" velocity = "2" /> <!-- limit is 30 Newton-meters, 2 m/s -->
        <axis xyz = "0 0 1" />
        <!-- you think it'd be 1 0 0 but this is what got the wheels to actually rotate forward. weird. -->
    </joint>

    

</robot>
